Workbook

Sheet Synthèse
A1: Fable — synthèse (tout est calculé depuis Hypothèses)
A3: PAR ABONNÉ / MOIS
A4: Modèle texte | B4: =Hypothèses!B28
A5: Plateforme de paiement | B5: =Hypothèses!B7
A6: Prix TTC | B6: =Unité!B4
A7: Ce qu'il te reste net (abonnement + crédits) | B7: =Unité!B10
A8: Ce que tu payes (API + images) | B8: =Unité!B19
A9: Marge brute / abonné | B9: =Unité!B22
A10: Taux de marge brute | B10: =Unité!B23
A12: COMBIEN DE CLIENTS
A13: Pour couvrir les coûts fixes | B13: =Unité!B28
A14: Pour couvrir coûts fixes + ton temps | B14: =Unité!B29
A15: Pour te payer 2 000 € / mois | B15: =Unité!B30
A17: SUR 12 MOIS
A18: Abonnés fin d'année | B18: =Prévision!M7
A19: Point mort cash | B19: =Prévision!B24
A20: Point mort après ton temps | B20: =Prévision!B25
A21: Résultat cash annuel | B21: =Prévision!N13
A22: Résultat annuel après ton temps | B22: =Prévision!N17
A24: COMPARATIF MODÈLES — marge brute / abonné / mois
A25: =Modèles!A4 | B25: =Modèles!I4
A26: =Modèles!A5 | B26: =Modèles!I5
A27: =Modèles!A6 | B27: =Modèles!I6
A28: =Modèles!A7 | B28: =Modèles!I7
A29: =Modèles!A8 | B29: =Modèles!I8
A31: Lecture : une marge brute négative sur une ligne = ce modèle ne peut pas être vendu 4,99 € avec cet usage. Ajuste le quota de chapitres (Hypothèses!B16) ou le prix.

Sheet Hypothèses
A1: Hypothèses — modifie uniquement les cellules en bleu (fond jaune = leviers clés)
A2: Bleu = saisie · Noir = formule · Vert = lien vers une autre feuille. Toutes les valeurs ci-dessous viennent de toi ou de nos échanges ; sources indiquées en colonne C.
A4: REVENUS
A5: Prix abonnement TTC (€ / mois) | B5: 4.99 | C5: Ta cible
A6: TVA | B6: 0.2 | C6: Services numériques en France : 20 %
A7: Plateforme de paiement | B7: Apple 15% | C7: Liste : Stripe / Apple 30% / Apple 15%
A8: Commission Stripe (%) | B8: 0.015 | C8: Cartes UE, ordre de grandeur — vérifie ton contrat
A9: Frais fixe Stripe (€ / transaction) | B9: 0.25
A10: Commission Apple standard | B10: 0.3 | C10: Achats in-app
A11: Commission Apple Small Business | B11: 0.15 | C11: < 1 M$ de CA annuel
A12: Prix d'une image vendue en crédit (€ TTC) | B12: 0.2 | C12: Crédits hors abonnement
A13: Images achetées en crédits / abonné / mois | B13: 4 | C13: Hypothèse de comportement — à mesurer en bêta
A15: USAGE PAR ABONNÉ
A16: Chapitres lus / abonné / mois | B16: 48 | C16: ≈ 2 livres de 24 chapitres
A17: Images incluses dans l'abonnement / mois | B17: 3 | C17: 0 si tout passe en crédits
A18: Chapitres par livre | B18: 24 | C18: Niveau « moyen »
A20: TOKENS PAR CHAPITRE (appel chapitre)
A21: Entrée non cachée (pilotage, dernier chapitre…) | B21: 1000 | C21: Tes logs cost_logs, sept. 2026
A22: Entrée cachée (bible, registre, règles) | B22: 4500 | C22: Idem — suppose que le cache fonctionne
A23: Sortie (texte + titre + choix) | B23: 3000 | C23: ≈ 1 400 mots FR
A24: Post-traitement entrée (résumé+état+plan, sur Luna) | B24: 9600 | C24: 3 appels parallèles
A25: Post-traitement sortie (sur Luna) | B25: 1100
A27: MODÈLE & IMAGES
A28: Modèle texte (chapitre / prologue) | B28: Claude Haiku 4.5 | C28: Liste : voir feuille Modèles
A29: Coût d'une image ($) | B29: 0.04 | C29: Imagen 4 Standard 0,04 $ ; Fast 0,02 $ ; Ultra 0,06 $ (2026)
A30: Taux de change : 1 € = x $ | B30: 1.08 | C30: À actualiser
A32: COÛTS FIXES MENSUELS (€ HT)
A33: Hébergement (Vercel) | B33: 20
A34: Base de données / auth (Supabase) | B34: 25
A35: Stockage images (R2 / Storage) | B35: 5
A36: Domaine, e-mails | B36: 3
A37: Outils, compta, banque | B37: 30
A38: Autre | B38: 0
A39: Total coûts fixes / mois | B39: =SUM(B33:B38)
A41: TON TEMPS (non décaissé, mais réel)
A42: Heures / mois | B42: 40
A43: Valorisation de ton heure (€) | B43: 40
A44: Coût du temps / mois | B44: =B42*B43
A46: CROISSANCE
A47: Abonnés payants au départ | B47: 0
...

Sheet Modèles
A1: Modèles de texte — coût par chapitre, par livre, par abonné (le modèle choisi est dans Hypothèses!B28)
A3: Modèle | B3: Entrée $/M | C3: Sortie $/M | D3: Cache lu $/M | E3: Coût chapitre ($) | F3: Coût livre ($) | G3: Coût texte / abonné / mois ($) | H3: Coût texte / abonné / mois (€) | I3: Marge brute / abonné (€) | J3: Source / note
A4: GPT-5.6 Luna | B4: 0.2 | C4: 1.2 | D4: 0.02 | E4: =(Hypothèses!$B$21*B4+Hypothèses!$B$22*D4+Hypothèses!$B$23*C4)/1000000+(Hypothèses!$B$24*$B$4+Hypothèses!$B$25*$C$4)/1000000 | F4: =E4*Hypothèses!$B$18 | G4: =E4*Hypothèses!$B$16 | H4: =G4/Hypothèses!$B$30 | I4: =Unité!$B$10-H4-Unité!$B$16 | J4: OpenAI docs, sept. 2026 (tier nano)
A5: Claude Haiku 4.5 | B5: 1 | C5: 5 | D5: 0.1 | E5: =(Hypothèses!$B$21*B5+Hypothèses!$B$22*D5+Hypothèses!$B$23*C5)/1000000+(Hypothèses!$B$24*$B$4+Hypothèses!$B$25*$C$4)/1000000 | F5: =E5*Hypothèses!$B$18 | G5: =E5*Hypothèses!$B$16 | H5: =G5/Hypothèses!$B$30 | I5: =Unité!$B$10-H5-Unité!$B$16 | J5: Anthropic, sept. 2026 ; cache lu = 10 % de l'entrée
A6: GPT-5.6 Terra | B6: 2 | C6: 12 | D6: 0.2 | E6: =(Hypothèses!$B$21*B6+Hypothèses!$B$22*D6+Hypothèses!$B$23*C6)/1000000+(Hypothèses!$B$24*$B$4+Hypothèses!$B$25*$C$4)/1000000 | F6: =E6*Hypothèses!$B$18 | G6: =E6*Hypothèses!$B$16 | H6: =G6/Hypothèses!$B$30 | I6: =Unité!$B$10-H6-Unité!$B$16 | J6: OpenAI, sept. 2026 ; cache lu supposé 10 % (à vérifier)
A7: Claude Sonnet 5 | B7: 3 | C7: 15 | D7: 0.3 | E7: =(Hypothèses!$B$21*B7+Hypothèses!$B$22*D7+Hypothèses!$B$23*C7)/1000000+(Hypothèses!$B$24*$B$4+Hypothèses!$B$25*$C$4)/1000000 | F7: =E7*Hypothèses!$B$18 | G7: =E7*Hypothèses!$B$16 | H7: =G7/Hypothèses!$B$30 | I7: =Unité!$B$10-H7-Unité!$B$16 | J7: Anthropic ; promo 2/10 $ terminée le 31/08/2026 — vérifier
A8: Claude Fable 5.1 | B8: 10 | C8: 50 | D8: 0.25 | E8: =(Hypothèses!$B$21*B8+Hypothèses!$B$22*D8+Hypothèses!$B$23*C8)/1000000+(Hypothèses!$B$24*$B$4+Hypothèses!$B$25*$C$4)/1000000 | F8: =E8*Hypothèses!$B$18 | G8: =E8*Hypothèses!$B$16 | H8: =G8/Hypothèses!$B$30 | I8: =Unité!$B$10-H8-Unité!$B$16 | J8: Anthropic, sept. 2026
A10: Le post-traitement (résumé, état, plan) tourne toujours sur Luna (ligne 4), quel que soit le modèle du chapitre.
A11: Marge brute / abonné = revenu net abonnement − coût texte − coût des images incluses (crédits exclus, voir Unité).

Sheet Unité
A1: Économie par abonné et par mois
A3: REVENUS (par abonné / mois)
A4: Abonnement TTC | B4: =Hypothèses!B5
A5: Abonnement HT (après TVA) | B5: =B4/(1+Hypothèses!B6)
A6: Commission plateforme sur l'abonnement | B6: =IF(Hypothèses!B7="Stripe",Hypothèses!B8*B4+Hypothèses!B9,IF(Hypothèses!B7="Apple 30%",Hypothèses!B10*B4,Hypothèses!B11*B4))
A7: Revenu net abonnement | B7: =B5-B6
A8: Crédits images vendus TTC | B8: =Hypothèses!B12*Hypothèses!B13
A9: Revenu net crédits (HT, après commission %) | B9: =B8/(1+Hypothèses!B6)-B8*IF(Hypothèses!B7="Stripe",Hypothèses!B8,IF(Hypothèses!B7="Apple 30%",Hypothèses!B10,Hypothèses!B11))
A10: Revenu net total / abonné | B10: =B7+B9
A12: COÛTS VARIABLES (par abonné / mois)
A13: Modèle choisi | B13: =Hypothèses!B28
A14: Coût texte par chapitre ($) | B14: =INDEX(Modèles!E4:E8,MATCH(B13,Modèles!A4:A8,0))
A15: Coût texte / mois ($) | B15: =B14*Hypothèses!B16
A16: Coût des images incluses (€) | B16: =Hypothèses!B17*Hypothèses!B29/Hypothèses!B30
A17: Coût des images vendues en crédits (€) | B17: =Hypothèses!B13*Hypothèses!B29/Hypothèses!B30
A18: Coût texte / mois (€) | B18: =B15/Hypothèses!B30
A19: Coût variable total / abonné (€) | B19: =B16+B17+B18
A21: MARGE
A22: Marge brute / abonné / mois (€) | B22: =B10-B19
A23: Taux de marge brute | B23: =IF(B10=0,0,B22/B10)
A24: Part des coûts variables dans le prix TTC | B24: =IF(B4=0,0,B19/B4)
A25: Marge sur les crédits images seuls (€) | B25: =B9-B17
A27: SEUILS
A28: Abonnés pour couvrir les coûts fixes | B28: =IF(B22<=0,"marge nulle",ROUNDUP(Hypothèses!B39/B22,0))
A29: Abonnés pour couvrir coûts fixes + ton temps | B29: =IF(B22<=0,"marge nulle",ROUNDUP((Hypothèses!B39+Hypothèses!B44)/B22,0))
A30: Abonnés pour te payer 2 000 € / mois net de tout | B30: =IF(B22<=0,"marge nulle",ROUNDUP((Hypothèses!B39+2000)/B22,0))

Sheet Prévision
A1: Prévision sur 12 mois (€)
A3: Mois | B3: M1 | C3: M2 | D3: M3 | E3: M4 | F3: M5 | G3: M6 | H3: M7 | I3: M8 | J3: M9 | K3: M10 | L3: M11 | M3: M12 | N3: Total / Fin
A4: Nouveaux abonnés | B4: =Hypothèses!$B$48*(1+Hypothèses!$B$49)^(1-1) | C4: =Hypothèses!$B$48*(1+Hypothèses!$B$49)^(2-1) | D4: =Hypothèses!$B$48*(1+Hypothèses!$B$49)^(3-1) | E4: =Hypothèses!$B$48*(1+Hypothèses!$B$49)^(4-1) | F4: =Hypothèses!$B$48*(1+Hypothèses!$B$49)^(5-1) | G4: =Hypothèses!$B$48*(1+Hypothèses!$B$49)^(6-1) | H4: =Hypothèses!$B$48*(1+Hypothèses!$B$49)^(7-1) | I4: =Hypothèses!$B$48*(1+Hypothèses!$B$49)^(8-1) | J4: =Hypothèses!$B$48*(1+Hypothèses!$B$49)^(9-1) | K4: =Hypothèses!$B$48*(1+Hypothèses!$B$49)^(10-1) | L4: =Hypothèses!$B$48*(1+Hypothèses!$B$49)^(11-1) | M4: =Hypothèses!$B$48*(1+Hypothèses!$B$49)^(12-1) | N4: =SUM(B4:M4)
A5: Abonnés en début de mois | B5: =Hypothèses!$B$47 | C5: =B7 | D5: =C7 | E5: =D7 | F5: =E7 | G5: =F7 | H5: =G7 | I5: =H7 | J5: =I7 | ... M5: =L7
A6: Désabonnements | B6: =B5*Hypothèses!$B$50 | C6: =C5*Hypothèses!$B$50 | D6: =D5*Hypothèses!$B$50 | E6: =E5*Hypothèses!$B$50 | F6: =F5*Hypothèses!$B$50 | G6: =G5*Hypothèses!$B$50 | H6: =H5*Hypothèses!$B$50 | I6: =I5*Hypothèses!$B$50 | ... M6: =M5*Hypothèses!$B$50 | N6: =SUM(B6:M6)
A7: Abonnés facturés (fin de mois) | B7: =B5+B4-B6 | C7: =C5+C4-C6 | D7: =D5+D4-D6 | E7: =E5+E4-E6 | F7: =F5+F4-F6 | G7: =G5+G4-G6 | H7: =H5+H4-H6 | I7: =I5+I4-I6 | ... M7: =M5+M4-M6 | N7: =M7
A9: Revenu net (abonnements + crédits) | B9: =B7*Unité!$B$10 | C9: =C7*Unité!$B$10 | D9: =D7*Unité!$B$10 | E9: =E7*Unité!$B$10 | F9: =F7*Unité!$B$10 | G9: =G7*Unité!$B$10 | H9: =H7*Unité!$B$10 | I9: =I7*Unité!$B$10 | ... M9: =M7*Unité!$B$10 | N9: =SUM(B9:M9)
A10: Coûts variables (API texte + images) | B10: =B7*Unité!$B$19 | C10: =C7*Unité!$B$19 | D10: =D7*Unité!$B$19 | E10: =E7*Unité!$B$19 | F10: =F7*Unité!$B$19 | G10: =G7*Unité!$B$19 | H10: =H7*Unité!$B$19 | I10: =I7*Unité!$B$19 | ... M10: =M7*Unité!$B$19 | N10: =SUM(B10:M10)
A11: Marge brute | B11: =B9-B10 | C11: =C9-C10 | D11: =D9-D10 | E11: =E9-E10 | F11: =F9-F10 | G11: =G9-G10 | H11: =H9-H10 | I11: =I9-I10 | ... M11: =M9-M10 | N11: =SUM(B11:M11)
A12: Coûts fixes | B12: =Hypothèses!$B$39 | C12: =Hypothèses!$B$39 | D12: =Hypothèses!$B$39 | E12: =Hypothèses!$B$39 | F12: =Hypothèses!$B$39 | G12: =Hypothèses!$B$39 | H12: =Hypothèses!$B$39 | I12: =Hypothèses!$B$39 | ... M12: =Hypothèses!$B$39 | N12: =SUM(B12:M12)
A13: Résultat cash du mois | B13: =B11-B12 | C13: =C11-C12 | D13: =D11-D12 | E13: =E11-E12 | F13: =F11-F12 | G13: =G11-G12 | H13: =H11-H12 | I13: =I11-I12 | ... M13: =M11-M12 | N13: =SUM(B13:M13)
A14: Résultat cash cumulé | B14: =B13 | C14: =B14+C13 | D14: =C14+D13 | E14: =D14+E13 | F14: =E14+F13 | G14: =F14+G13 | H14: =G14+H13 | I14: =H14+I13 | J14: =I14+J13 | ... M14: =L14+M13 | N14: =M14
A16: Coût de ton temps | B16: =Hypothèses!$B$44 | C16: =Hypothèses!$B$44 | D16: =Hypothèses!$B$44 | E16: =Hypothèses!$B$44 | F16: =Hypothèses!$B$44 | G16: =Hypothèses!$B$44 | H16: =Hypothèses!$B$44 | I16: =Hypothèses!$B$44 | ... M16: =Hypothèses!$B$44 | N16: =SUM(B16:M16)
A17: Résultat après ton temps | B17: =B13-B16 | C17: =C13-C16 | D17: =D13-D16 | E17: =E13-E16 | F17: =F13-F16 | G17: =G13-G16 | H17: =H13-H16 | I17: =I13-I16 | ... M17: =M13-M16 | N17: =SUM(B17:M17)
A18: Cumulé après ton temps | B18: =B17 | C18: =B18+C17 | D18: =C18+D17 | E18: =D18+E17 | F18: =E18+F17 | G18: =F18+G17 | H18: =G18+H17 | I18: =H18+I17 | J18: =I18+J17 | ... M18: =L18+M17 | N18: =M18
A20: Flag : cumul cash ≥ 0 | B20: =IF(B14>=0,1,0) | C20: =IF(C14>=0,1,0) | D20: =IF(D14>=0,1,0) | E20: =IF(E14>=0,1,0) | F20: =IF(F14>=0,1,0) | G20: =IF(G14>=0,1,0) | H20: =IF(H14>=0,1,0) | I20: =IF(I14>=0,1,0) | ... M20: =IF(M14>=0,1,0)
A21: Flag : cumul après temps ≥ 0 | B21: =IF(B18>=0,1,0) | C21: =IF(C18>=0,1,0) | D21: =IF(D18>=0,1,0) | E21: =IF(E18>=0,1,0) | F21: =IF(F18>=0,1,0) | G21: =IF(G18>=0,1,0) | H21: =IF(H18>=0,1,0) | I21: =IF(I18>=0,1,0) | ... M21: =IF(M18>=0,1,0)
A23: POINT MORT
A24: Mois où le cumul cash devient ≥ 0 | B24: =IFERROR("M"&MATCH(1,B20:M20,0),"pas dans les 12 mois")
A25: Mois où le cumul couvre aussi ton temps | B25: =IFERROR("M"&MATCH(1,B21:M21,0),"pas dans les 12 mois")
A26: Abonnés en fin d'année | B26: =M7
A27: Revenu annuel net | B27: =N9
A28: Résultat cash annuel | B28: =N13
A29: Résultat annuel après ton temps | B29: =N17
